Workbook
Name ACTION: #REF!
Name ACTION: #REF!

Sheet Cover
B2: TEST REPORT DOCUMENT
A4: Project Name | B4: SmartHire-AI | E4: Creator | F4: Nguyễn Minh Hiếu
A5: Project Code | B5: SA | E5: Issue Date | F5: 14/09/2026
A6: Document Code | B6: =B5&"_Test Report_"&F6 -> SA_Test Report_v1.0 | E6: Version | F6: v1.0
A9: Record of change
A10: Effective Date | B10: Version | C10: Change Item | D10: *A,D,M | E10: Change description | F10: Reference
A11: 14/10/2026 | B11: v1.0 | C11: Test Report | D11: A | E11: Initial release: system test cases for 53 features (8 Master platform modules, 45 Tenant modules). | F11: SmartHire-AI feature specifications (docs/features), Report5_Unit Test

Sheet Test Cases
D1: TEST CASE LIST
B3: Project Name | D3: =Cover!B4 -> SmartHire-AI
B4: Project Code | D4: =IF(Cover!B5="","",Cover!B5) -> SA
B5: Test Environment Setup Description | D5: 1. Server: Spring Boot 3 backend (Java 21) and React 19 frontend served by Nginx (Docker Compose). 2. Database: PostgreSQL master DB (smarthire_master) and one MySQL database per tenant; Redis; RabbitMQ. 3. Web browser: latest Google Chrome / Microsoft Edge. 4. Test data: at least two ACTIVE tenants (tenant A, tenant B) with Tenant Admin, HR, Recruiter and Candidate accounts; one Workspace Admin account on the master platform.
B8: No | C8: Function Name | D8: Sheet Name | E8: Description | F8: Pre-Condition
B9: 1 | C9: Tenant Onboarding, Deferred Provisioning & Lifecycle | D9: MASTER-01 | E9: Verify the business rules and APIs of MASTER-01 - Tenant Onboarding, Deferred Provisioning & Lifecycle as specified in docs/features/Authentication/Tenant-Onboarding.md. | F9: Master platform is running; a Workspace Admin account exists.
B10: 2 | C10: Two-Tier B2B Subscription Plans, V27 Snapshot & Quotas | D10: MASTER-02 | E10: Verify the business rules and APIs of MASTER-02 - Two-Tier B2B Subscription Plans, V27 Snapshot & Quotas as specified in docs/features/Master-Platform/Subscription-Plans-Quotas.md. | F10: Master platform is running; a Workspace Admin account exists.
B11: 3 | C11: Billing, VAT Invoicing & Payment Gateways (SePay/VNPay/PayPal) | D11: MASTER-03 | E11: Verify the business rules and APIs of MASTER-03 - Billing, VAT Invoicing & Payment Gateways (SePay/VNPay/PayPal) as specified in docs/features/Master-Platform/Billing-Invoicing-Payment.md. | F11: Master platform is running; a Workspace Admin account exists.
B12: 4 | C12: Self-serve Checkout & Click-wrap Legal Consent (Decree 13/2023/ND-CP) | D12: MASTER-04 | E12: Verify the business rules and APIs of MASTER-04 - Self-serve Checkout & Click-wrap Legal Consent (Decree 13/2023/ND-CP) as specified in docs/features/Master-Platform/Checkout-Clickwrap-Consent.md. | F12: Master platform is running; a Workspace Admin account exists.
B13: 5 | C13: B2B Electronic Contracts & Dropbox Sign API v3 Integration | D13: MASTER-05 | E13: Verify the business rules and APIs of MASTER-05 - B2B Electronic Contracts & Dropbox Sign API v3 Integration as specified in docs/features/Master-Platform/B2B-EContracts-DropboxSign.md. | F13: Master platform is running; a Workspace Admin account exists.
B14: 6 | C14: Enterprise Sales Leads & 4-Step B2B Deal Wizard | D14: MASTER-06 | E14: Verify the business rules and APIs of MASTER-06 - Enterprise Sales Leads & 4-Step B2B Deal Wizard as specified in docs/features/Master-Platform/Sales-Leads-B2B-Deal-Wizard.md. | F14: Master platform is running; a Workspace Admin account exists.
B15: 7 | C15: AI Engine Governance, Model Routing & Token Cost Metering | D15: MASTER-07 | E15: Verify the business rules and APIs of MASTER-07 - AI Engine Governance, Model Routing & Token Cost Metering as specified in docs/features/Master-Platform/AI-Governance-Metering.md. | F15: Master platform is running; a Workspace Admin account exists.
B16: 8 | C16: Platform Financial Analytics (ARR/NRR), Audit Logs & Auto Email Alerts | D16: MASTER-08 | E16: Verify the business rules and APIs of MASTER-08 - Platform Financial Analytics (ARR/NRR), Audit Logs & Auto Email Alerts as specified in docs/features/Master-Platform/Platform-Analytics-Notifications.md. | F16: Master platform is running; a Workspace Admin account exists.
B17: 9 | C17: Multiple Choice Test | D17: ASSESS-01 | E17: Verify the business rules and APIs of ASSESS-01 - Multiple Choice Test as specified in docs/features/Technical-Assessment/Multiple-Choice-Test.md. | F17: Tenant A and tenant B are ACTIVE; a Recruiter account exists in tenant A.
B18: 10 | C18: Coding Challenge | D18: ASSESS-02 | E18: Verify the business rules and APIs of ASSESS-02 - Coding Challenge as specified in docs/features/Technical-Assessment/Coding-Challenge.md. | F18: Tenant A and tenant B are ACTIVE; a Recruiter account exists in tenant A.
B19: 11 | C19: Auto Grading | D19: ASSESS-03 | E19: Verify the business rules and APIs of ASSESS-03 - Auto Grading as specified in docs/features/Technical-Assessment/Auto-Grading.md. | F19: Tenant A and tenant B are ACTIVE; a Recruiter account exists in tenant A.
B20: 12 | C20: Timer Control | D20: ASSESS-04 | E20: Verify the business rules and APIs of ASSESS-04 - Timer Control as specified in docs/features/Technical-Assessment/Timer-Control.md. | F20: Tenant A and tenant B are ACTIVE; a Candidate account exists in tenant A.
... B61: 53 | C61: Hiring Decision Management | D61: WF-03 | E61: Verify the business rules and APIs of WF-03 - Hiring Decision Management as specified in docs/features/Recruitment-Workflow/Hiring-Decision.md. | F61: Tenant A and tenant B are ACTIVE; a Admin account exists in tenant A.

Sheet Test Statistics
B1: TEST STATISTICS
B3: Project Name | C3: =Cover!B4 -> SmartHire-AI | E3: Creator
B4: Project Code | C4: =IF(Cover!B5="","",Cover!B5) -> SA | E4: Reviewer/Approver
B5: Document Code | C5: =Cover!B6 -> SA_Test Report_v1.0 | E5: Issue Date | H5: 14/10/2026
B6: Notes | C6: This release includes 53 features: 8 Master platform modules and 45 Tenant modules.
B10: No | C10: Module code | D10: Passed | E10: Failed | F10: Pending | G10: N/A | H10: Number of test cases
B11: 1 | C11: ='MASTER-01'!B2 -> Tenant Onboarding, Deferred Provisioning & Lifecycle | D11: ='MASTER-01'!B6 -> 0 | E11: ='MASTER-01'!C6 -> 19 | F11: ='MASTER-01'!D6 -> 0 | G11: ='MASTER-01'!E6 -> 0 | H11: ='MASTER-01'!B4 -> 19
B12: 2 | C12: ='MASTER-02'!B2 -> Two-Tier B2B Subscription Plans, V27 Snapshot & Quotas | D12: ='MASTER-02'!B6 -> 16 | E12: ='MASTER-02'!C6 -> 0 | F12: ='MASTER-02'!D6 -> 0 | G12: ='MASTER-02'!E6 -> 0 | H12: ='MASTER-02'!B4 -> 16
B13: 3 | C13: ='MASTER-03'!B2 -> Billing, VAT Invoicing & Payment Gateways (SePay/VNPay/PayPal) | D13: ='MASTER-03'!B6 -> 0 | E13: ='MASTER-03'!C6 -> 20 | F13: ='MASTER-03'!D6 -> 0 | G13: ='MASTER-03'!E6 -> 0 | H13: ='MASTER-03'!B4 -> 20
B14: 4 | C14: ='MASTER-04'!B2 -> Self-serve Checkout & Click-wrap Legal Consent (Decree 13/2023/ND-CP) | D14: ='MASTER-04'!B6 -> 0 | E14: ='MASTER-04'!C6 -> 4 | F14: ='MASTER-04'!D6 -> 0 | G14: ='MASTER-04'!E6 -> 2 | H14: ='MASTER-04'!B4 -> 6
B15: 5 | C15: ='MASTER-05'!B2 -> B2B Electronic Contracts & Dropbox Sign API v3 Integration | D15: ='MASTER-05'!B6 -> 23 | E15: ='MASTER-05'!C6 -> 0 | F15: ='MASTER-05'!D6 -> 0 | G15: ='MASTER-05'!E6 -> 0 | H15: ='MASTER-05'!B4 -> 23
B16: 6 | C16: ='MASTER-06'!B2 -> Enterprise Sales Leads & 4-Step B2B Deal Wizard | D16: ='MASTER-06'!B6 -> 0 | E16: ='MASTER-06'!C6 -> 0 | F16: ='MASTER-06'!D6 -> 8 | G16: ='MASTER-06'!E6 -> 0 | H16: ='MASTER-06'!B4 -> 8
B17: 7 | C17: ='MASTER-07'!B2 -> AI Engine Governance, Model Routing & Token Cost Metering | D17: ='MASTER-07'!B6 -> 0 | E17: ='MASTER-07'!C6 -> 27 | F17: ='MASTER-07'!D6 -> 0 | G17: ='MASTER-07'!E6 -> 0 | H17: ='MASTER-07'!B4 -> 27
B18: 8 | C18: ='MASTER-08'!B2 -> Platform Financial Analytics (ARR/NRR), Audit Logs & Auto Email Alerts | D18: ='MASTER-08'!B6 -> 0 | E18: ='MASTER-08'!C6 -> 0 | F18: ='MASTER-08'!D6 -> 5 | G18: ='MASTER-08'!E6 -> 0 | H18: ='MASTER-08'!B4 -> 5
B19: 9 | C19: ='ASSESS-01'!B2 -> Multiple Choice Test | D19: ='ASSESS-01'!B6 -> 38 | E19: ='ASSESS-01'!C6 -> 0 | F19: ='ASSESS-01'!D6 -> 0 | G19: ='ASSESS-01'!E6 -> 0 | H19: ='ASSESS-01'!B4 -> 38
B20: 10 | C20: ='ASSESS-02'!B2 -> Coding Challenge | D20: ='ASSESS-02'!B6 -> 0 | E20: ='ASSESS-02'!C6 -> 0 | F20: ='ASSESS-02'!D6 -> 5 | G20: ='ASSESS-02'!E6 -> 0 | H20: ='ASSESS-02'!B4 -> 5
B21: 11 | C21: ='ASSESS-03'!B2 -> Auto Grading | D21: ='ASSESS-03'!B6 -> 0 | E21: ='ASSESS-03'!C6 -> 0 | F21: ='ASSESS-03'!D6 -> 0 | G21: ='ASSESS-03'!E6 -> 0 | H21: ='ASSESS-03'!B4 -> 0
B22: 12 | C22: ='ASSESS-04'!B2 -> Timer Control | D22: ='ASSESS-04'!B6 -> 5 | E22: ='ASSESS-04'!C6 -> 0 | F22: ='ASSESS-04'!D6 -> 0 | G22: ='ASSESS-04'!E6 -> 0 | H22: ='ASSESS-04'!B4 -> 5
B23: 13 | C23: ='ASSESS-05'!B2 -> Anti-cheating Detection | D23: ='ASSESS-05'!B6 -> 4 | E23: ='ASSESS-05'!C6 -> 0 | F23: ='ASSESS-05'!D6 -> 3 | G23: ='ASSESS-05'!E6 -> 0 | H23: ='ASSESS-05'!B4 -> 7
B24: 14 | C24: ='AUTH-01'!B2 -> User Registration | D24: ='AUTH-01'!B6 -> 0 | E24: ='AUTH-01'!C6 -> 0 | F24: ='AUTH-01'!D6 -> 4 | G24: ='AUTH-01'!E6 -> 0 | H24: ='AUTH-01'!B4 -> 4
B25: 15 | C25: ='AUTH-02'!B2 -> Login & JWT Authentication | D25: ='AUTH-02'!B6 -> 18 | E25: ='AUTH-02'!C6 -> 0 | F25: ='AUTH-02'!D6 -> 0 | G25: ='AUTH-02'!E6 -> 0 | H25: ='AUTH-02'!B4 -> 18
B26: 16 | C26: ='AUTH-03'!B2 -> Google OAuth Login | D26: ='AUTH-03'!B6 -> 2 | E26: ='AUTH-03'!C6 -> 0 | F26: ='AUTH-03'!D6 -> 0 | G26: ='AUTH-03'!E6 -> 2 | H26: ='AUTH-03'!B4 -> 4
B27: 17 | C27: ='AUTH-04'!B2 -> Role-Based Access Control (RBAC) | D27: ='AUTH-04'!B6 -> 17 | E27: ='AUTH-04'!C6 -> 0 | F27: ='AUTH-04'!D6 -> 0 | G27: ='AUTH-04'!E6 -> 0 | H27: ='AUTH-04'!B4 -> 17
B28: 18 | C28: ='AUTH-05'!B2 -> User Profile Management | D28: ='AUTH-05'!B6 -> 0 | E28: ='AUTH-05'!C6 -> 0 | F28: ='AUTH-05'!D6 -> 7 | G28: ='AUTH-05'!E6 -> 0 | H28: ='AUTH-05'!B4 -> 7
B29: 19 | C29: ='COMPANY-01'!B2 -> View & Update Company Profile | D29: ='COMPANY-01'!B6 -> 8 | E29: ='COMPANY-01'!C6 -> 0 | F29: ='COMPANY-01'!D6 -> 0 | G29: ='COMPANY-01'!E6 -> 0 | H29: ='COMPANY-01'!B4 -> 8
B30: 20 | C30: ='COMPANY-02'!B2 -> Invite tenant staff | D30: ='COMPANY-02'!B6 -> 10 | E30: ='COMPANY-02'!C6 -> 0 | F30: ='COMPANY-02'!D6 -> 0 | G30: ='COMPANY-02'!E6 -> 0 | H30: ='COMPANY-02'!B4 -> 10
B31: 21 | C31: ='COMPANY-02-Tenant-Landing-Page'!B2 -> Tenant Landing / Career Page | D31: ='COMPANY-02-Tenant-Landing-Page'!B6 -> 7 | E31: ='COMPANY-02-Tenant-Landing-Page'!C6 -> 0 | F31: ='COMPANY-02-Tenant-Landing-Page'!D6 -> 0 | G31: ='COMPANY-02-Tenant-Landing-Page'!E6 -> 0 | H31: ='COMPANY-02-Tenant-Landing-Page'!B4 -> 7
B32: 22 | C32: ='CV-01'!B2 -> CV Upload | D32: ='CV-01'!B6 -> 9 | E32: ='CV-01'!C6 -> 0 | F32: ='CV-01'!D6 -> 0 | G32: ='CV-01'!E6 -> 0 | H32: ='CV-01'!B4 -> 9
B33: 23 | C33: ='CV-02'!B2 -> CV Parsing | D33: ='CV-02'!B6 -> 5 | E33: ='CV-02'!C6 -> 0 | F33: ='CV-02'!D6 -> 0 | G33: ='CV-02'!E6 -> 0 | H33: ='CV-02'!B4 -> 5
B34: 24 | C34: ='CV-03'!B2 -> Information Extraction | D34: ='CV-03'!B6 -> 5 | E34: ='CV-03'!C6 -> 0 | F34: ='CV-03'!D6 -> 0 | G34: ='CV-03'!E6 -> 0 | H34: ='CV-03'!B4 -> 5
B35: 25 | C35: ='CV-04'!B2 -> AI Skill Analysis | D35: ='CV-04'!B6 -> 4 | E35: ='CV-04'!C6 -> 0 | F35: ='CV-04'!D6 -> 0 | G35: ='CV-04'!E6 -> 0 | H35: ='CV-04'!B4 -> 4
B36: 26 | C36: ='CV-05'!B2 -> Candidate Matching Score | D36: ='CV-05'!B6 -> 7 | E36: ='CV-05'!C6 -> 0 | F36: ='CV-05'!D6 -> 0 | G36: ='CV-05'!E6 -> 0 | H36: ='CV-05'!B4 -> 7
B37: 27 | C37: ='CV-06'!B2 -> CV Builder | D37: ='CV-06'!B6 -> 25 | E37: ='CV-06'!C6 -> 0 | F37: ='CV-06'!D6 -> 0 | G37: ='CV-06'!E6 -> 0 | H37: ='CV-06'!B4 -> 25
B38: 28 | C38: ='DASH-01'!B2 -> Recruitment Statistics | D38: ='DASH-01'!B6 -> 6 | E38: ='DASH-01'!C6 -> 0 | F38: ='DASH-01'!D6 -> 0 | G38: ='DASH-01'!E6 -> 0 | H38: ='DASH-01'!B4 -> 6
B39: 29 | C39: ='DASH-02'!B2 -> Dashboard Charts | D39: ='DASH-02'!B6 -> 5 | E39: ='DASH-02'!C6 -> 0 | F39: ='DASH-02'!D6 -> 0 | G39: ='DASH-02'!E6 -> 0 | H39: ='DASH-02'!B4 -> 5
B40: 30 | C40: ='DASH-03'!B2 -> Recruitment Trend Analysis | D40: ='DASH-03'!B6 -> 4 | E40: ='DASH-03'!C6 -> 0 | F40: ='DASH-03'!D6 -> 0 | G40: ='DASH-03'!E6 -> 0 | H40: ='DASH-03'!B4 -> 4
B41: 31 | C41: ='INT-01'!B2 -> AI Question Generation | D41: ='INT-01'!B6 -> 35 | E41: ='INT-01'!C6 -> 0 | F41: ='INT-01'!D6 -> 6 | G41: ='INT-01'!E6 -> 0 | H41: ='INT-01'!B4 -> 41
B42: 32 | C42: ='INT-02'!B2 -> Speech-to-Text Integration | D42: ='INT-02'!B6 -> 17 | E42: ='INT-02'!C6 -> 0 | F42: ='INT-02'!D6 -> 0 | G42: ='INT-02'!E6 -> 0 | H42: ='INT-02'!B4 -> 17
B43: 33 | C43: ='INT-03'!B2 -> NLP Response Analysis | D43: ='INT-03'!B6 -> 5 | E43: ='INT-03'!C6 -> 0 | F43: ='INT-03'!D6 -> 0 | G43: ='INT-03'!E6 -> 0 | H43: ='INT-03'!B4 -> 5
B44: 34 | C44: ='INT-04'!B2 -> AI Interview Scoring | D44: ='INT-04'!B6 -> 8 | E44: ='INT-04'!C6 -> 0 | F44: ='INT-04'!D6 -> 0 | G44: ='INT-04'!E6 -> 0 | H44: ='INT-04'!B4 -> 8
...

Sheet MASTER-01
A2: Feature | B2: Tenant Onboarding, Deferred Provisioning & Lifecycle | R2: Passed
A3: Test requirement | B3: Verify the business rules and APIs of MASTER-01 - Tenant Onboarding, Deferred Provisioning & Lifecycle as specified in docs/features/Authentication/Tenant-Onboarding.md. | R3: Failed
A4: Number of TCs | B4: =COUNTIF(A11:A2000,"*-TC*") -> 19 | R4: Pending
A5: Testing Round | B5: Passed | C5: Failed | D5: Pending | E5: N/A | R5: N/A
A6: Round 1 | B6: =COUNTIF($F$11:$F$2000,B$5) -> 0 | C6: =COUNTIF($F$11:$F$2000,C$5) -> 19 | D6: =COUNTIF($F$11:$F$2000,D$5) -> 0 | E6: =COUNTIF($F$11:$F$2000,E$5) -> 0
A7: Round 2 | B7: =COUNTIF($I$11:$I$2000,B$5) -> 0 | C7: =COUNTIF($I$11:$I$2000,C$5) -> 0 | D7: =COUNTIF($I$11:$I$2000,D$5) -> 0 | E7: =COUNTIF($I$11:$I$2000,E$5) -> 0
A8: Round 3 | B8: =COUNTIF($L$11:$L$2000,B$5) -> 0 | C8: =COUNTIF($L$11:$L$2000,C$5) -> 0 | D8: =COUNTIF($L$11:$L$2000,D$5) -> 0 | E8: =COUNTIF($L$11:$L$2000,E$5) -> 0
A10: Test Case ID | B10: Test Case Description | C10: Test Case Procedure | D10: Expected Results | E10: Pre-conditions | F10: Round 1 | G10: Test date | H10: Tester | I10: Round 2 | J10: Test date | K10: Tester | L10: Round 3 | M10: Test date | N10: Tester | O10: Note
A11: Get all tenants (GET /api/v1/master/tenants)
A12: MASTER-01-TC24 | B12: Verify get all tenants succeeds with valid input (GET /api/v1/master/tenants). | C12: 1. Log in as Workspace Admin. 2. Send GET /api/v1/master/tenants. 3. Check the response and the data shown in the system. | D12: HTTP 200. Response success = true and contains the requested data. | E12: Master platform is running. The Workspace Admin account has permission for this action. | F12: Failed | G12: 14/10/2026 | H12: Nguyễn Nhất Sinh | O12: Failing automated tests: MultiDatabaseIntegrationTest.authenticatedOnboardApiCreatesTenantAndRejectsDuplicateAliases
A13: Check subdomain exists (GET /api/v1/master/tenants/check-subdomain/{id})
A14: MASTER-01-TC25 | B14: Verify check subdomain exists succeeds with valid input (GET /api/v1/master/tenants/check-subdomain/{id}). | C14: 1. Do not log in (public endpoint). 2. Send GET /api/v1/master/tenants/check-subdomain/{id}. 3. Check the response and the data shown in the system. | D14: HTTP 200. Response success = true and contains the requested data. | E14: Master platform is running. The target resource exists. | F14: Failed | G14: 14/10/2026 | H14: Nguyễn Nhất Sinh | O14: Failing automated tests: MultiDatabaseIntegrationTest.authenticatedOnboardApiCreatesTenantAndRejectsDuplicateAliases
A15: Db (POST /api/v1/master/tenants/onboard)
A16: MASTER-01-TC26 | B16: Verify db succeeds with valid input (POST /api/v1/master/tenants/onboard). | C16: 1. Log in as Workspace Admin. 2. Send POST /api/v1/master/tenants/onboard and a valid request body. 3. Check the response and the data shown in the system. | D16: HTTP 200/201. Response success = true; the record/action is saved and returned in the response. | E16: Master platform is running. The Workspace Admin account has permission for this action. | F16: Failed | G16: 14/10/2026 | H16: Nguyễn Nhất Sinh | O16: Failing automated tests: MultiDatabaseIntegrationTest.authenticatedOnboardApiCreatesTenantAndRejectsDuplicateAliases
A17: MASTER-01-TC27 | B17: Verify db rejects invalid input (POST /api/v1/master/tenants/onboard). | C17: 1. Log in as Workspace Admin. 2. Send POST /api/v1/master/tenants/onboard with missing required fields or invalid values (empty text, wrong format, out-of-range numbers, non-existing IDs). 3. Check the response and the data in the system. | D17: HTTP 400 (or 404 for a non-existing ID) with success = false and an error message / field errors. No data is created or changed. | E17: Master platform is running. The Workspace Admin account has permission for this action. | F17: Failed | G17: 14/10/2026 | H17: Nguyễn Nhất Sinh | O17: Failing automated tests: MultiDatabaseIntegrationTest.authenticatedOnboardApiCreatesTenantAndRejectsDuplicateAliases
A18: Tenant (DELETE /api/v1/master/tenants/{id})
A19: MASTER-01-TC28 | B19: Verify tenant succeeds with valid input (DELETE /api/v1/master/tenants/{id}). | C19: 1. Log in as Workspace Admin. 2. Send DELETE /api/v1/master/tenants/{id}. 3. Check the response and the data shown in the system. | D19: HTTP 200/204. The record is removed (or archived) and no longer appears in lists. | E19: Master platform is running. The Workspace Admin account has permission for this action. The target resource exists. | F19: Failed | G19: 14/10/2026 | H19: Nguyễn Nhất Sinh | O19: Failing automated tests: MultiDatabaseIntegrationTest.authenticatedOnboardApiCreatesTenantAndRejectsDuplicateAliases
A20: MASTER-01-TC29 | B20: Verify tenant rejects invalid input (DELETE /api/v1/master/tenants/{id}). | C20: 1. Log in as Workspace Admin. 2. Send DELETE /api/v1/master/tenants/{id} with missing required fields or invalid values (empty text, wrong format, out-of-range numbers, non-existing IDs). 3. Check the response and the data in the system. | D20: HTTP 400 (or 404 for a non-existing ID) with success = false and an error message / field errors. No data is created or changed. | E20: Master platform is running. The Workspace Admin account has permission for this action. The target resource exists. | F20: Failed | G20: 14/10/2026 | H20: Nguyễn Nhất Sinh | O20: Failing automated tests: MultiDatabaseIntegrationTest.authenticatedOnboardApiCreatesTenantAndRejectsDuplicateAliases
A21: Get tenant by id (GET /api/v1/master/tenants/{id})
A22: MASTER-01-TC30 | B22: Verify get tenant by id succeeds with valid input (GET /api/v1/master/tenants/{id}). | C22: 1. Log in as Workspace Admin. 2. Send GET /api/v1/master/tenants/{id}. 3. Check the response and the data shown in the system. | D22: HTTP 200. Response success = true and contains the requested data. | E22: Master platform is running. The Workspace Admin account has permission for this action. The target resource exists. | F22: Failed | G22: 14/10/2026 | H22: Nguyễn Nhất Sinh | O22: Failing automated tests: MultiDatabaseIntegrationTest.authenticatedOnboardApiCreatesTenantAndRejectsDuplicateAliases
A23: Update tenant (PUT /api/v1/master/tenants/{id})
A24: MASTER-01-TC31 | B24: Verify update tenant succeeds with valid input (PUT /api/v1/master/tenants/{id}). | C24: 1. Log in as Workspace Admin. 2. Send PUT /api/v1/master/tenants/{id} and a valid request body. 3. Check the response and the data shown in the system. | D24: HTTP 200. Response success = true; the changes are saved and returned. | E24: Master platform is running. The Workspace Admin account has permission for this action. The target resource exists. | F24: Failed | G24: 14/10/2026 | H24: Nguyễn Nhất Sinh | O24: Failing automated tests: MultiDatabaseIntegrationTest.authenticatedOnboardApiCreatesTenantAndRejectsDuplicateAliases
A25: MASTER-01-TC32 | B25: Verify update tenant rejects invalid input (PUT /api/v1/master/tenants/{id}). | C25: 1. Log in as Workspace Admin. 2. Send PUT /api/v1/master/tenants/{id} with missing required fields or invalid values (empty text, wrong format, out-of-range numbers, non-existing IDs). 3. Check the response and the data in the system. | D25: HTTP 400 (or 404 for a non-existing ID) with success = false and an error message / field errors. No data is created or changed. | E25: Master platform is running. The Workspace Admin account has permission for this action. The target resource exists. | F25: Failed | G25: 14/10/2026 | H25: Nguyễn Nhất Sinh | O25: Failing automated tests: MultiDatabaseIntegrationTest.authenticatedOnboardApiCreatesTenantAndRejectsDuplicateAliases
A26: Restore tenant (POST /api/v1/master/tenants/{id}/restore)
A27: MASTER-01-TC33 | B27: Verify restore tenant succeeds with valid input (POST /api/v1/master/tenants/{id}/restore). | C27: 1. Log in as Workspace Admin. 2. Send POST /api/v1/master/tenants/{id}/restore and a valid request body. 3. Check the response and the data shown in the system. | D27: HTTP 200/201. Response success = true; the record/action is saved and returned in the response. | E27: Master platform is running. The Workspace Admin account has permission for this action. The target resource exists. | F27: Failed | G27: 14/10/2026 | H27: Nguyễn Nhất Sinh | O27: Failing automated tests: MultiDatabaseIntegrationTest.authenticatedOnboardApiCreatesTenantAndRejectsDuplicateAliases
A28: MASTER-01-TC34 | B28: Verify restore tenant rejects invalid input (POST /api/v1/master/tenants/{id}/restore). | C28: 1. Log in as Workspace Admin. 2. Send POST /api/v1/master/tenants/{id}/restore with missing required fields or invalid values (empty text, wrong format, out-of-range numbers, non-existing IDs). 3. Check the response and the data in the system. | D28: HTTP 400 (or 404 for a non-existing ID) with success = false and an error message / field errors. No data is created or changed. | E28: Master platform is running. The Workspace Admin account has permission for this action. The target resource exists. | F28: Failed | G28: 14/10/2026 | H28: Nguyễn Nhất Sinh | O28: Failing automated tests: MultiDatabaseIntegrationTest.authenticatedOnboardApiCreatesTenantAndRejectsDuplicateAliases
A29: Retry (POST /api/v1/master/tenants/{id}/retry)
A30: MASTER-01-TC35 | B30: Verify retry succeeds with valid input (POST /api/v1/master/tenants/{id}/retry). | C30: 1. Log in as Workspace Admin. 2. Send POST /api/v1/master/tenants/{id}/retry and a valid request body. 3. Check the response and the data shown in the system. | D30: HTTP 200/201. Response success = true; the record/action is saved and returned in the response. | E30: Master platform is running. The Workspace Admin account has permission for this action. The target resource exists. | F30: Failed | G30: 14/10/2026 | H30: Nguyễn Nhất Sinh | O30: Failing automated tests: MultiDatabaseIntegrationTest.authenticatedOnboardApiCreatesTenantAndRejectsDuplicateAliases
A31: MASTER-01-TC36 | B31: Verify retry rejects invalid input (POST /api/v1/master/tenants/{id}/retry). | C31: 1. Log in as Workspace Admin. 2. Send POST /api/v1/master/tenants/{id}/retry with missing required fields or invalid values (empty text, wrong format, out-of-range numbers, non-existing IDs). 3. Check the response and the data in the system. | D31: HTTP 400 (or 404 for a non-existing ID) with success = false and an error message / field errors. No data is created or changed. | E31: Master platform is running. The Workspace Admin account has permission for this action. The target resource exists. | F31: Failed | G31: 14/10/2026 | H31: Nguyễn Nhất Sinh | O31: Failing automated tests: MultiDatabaseIntegrationTest.authenticatedOnboardApiCreatesTenantAndRejectsDuplicateAliases
A32: Delete (PATCH /api/v1/master/tenants/{id}/soft-delete)
A33: MASTER-01-TC37 | B33: Verify delete succeeds with valid input (PATCH /api/v1/master/tenants/{id}/soft-delete). | C33: 1. Log in as Workspace Admin. 2. Send PATCH /api/v1/master/tenants/{id}/soft-delete and a valid request body. 3. Check the response and the data shown in the system. | D33: HTTP 200. Response success = true; the changed fields are saved. | E33: Master platform is running. The Workspace Admin account has permission for this action. The target resource exists. | F33: Failed | G33: 14/10/2026 | H33: Nguyễn Nhất Sinh | O33: Failing automated tests: MultiDatabaseIntegrationTest.authenticatedOnboardApiCreatesTenantAndRejectsDuplicateAliases
A34: MASTER-01-TC38 | B34: Verify delete rejects invalid input (PATCH /api/v1/master/tenants/{id}/soft-delete). | C34: 1. Log in as Workspace Admin. 2. Send PATCH /api/v1/master/tenants/{id}/soft-delete with missing required fields or invalid values (empty text, wrong format, out-of-range numbers, non-existing IDs). 3. Check the response and the data in the system. | D34: HTTP 400 (or 404 for a non-existing ID) with success = false and an error message / field errors. No data is created or changed. | E34: Master platform is running. The Workspace Admin account has permission for this action. The target resource exists. | F34: Failed | G34: 14/10/2026 | H34: Nguyễn Nhất Sinh | O34: Failing automated tests: MultiDatabaseIntegrationTest.authenticatedOnboardApiCreatesTenantAndRejectsDuplicateAliases
A35: Update tenant status (PATCH /api/v1/master/tenants/{id}/status)
A36: MASTER-01-TC39 | B36: Verify update tenant status succeeds with valid input (PATCH /api/v1/master/tenants/{id}/status). | C36: 1. Log in as Workspace Admin. 2. Send PATCH /api/v1/master/tenants/{id}/status and a valid request body. 3. Check the response and the data shown in the system. | D36: HTTP 200. Response success = true; the changed fields are saved. | E36: Master platform is running. The Workspace Admin account has permission for this action. The target resource exists. | F36: Failed | G36: 14/10/2026 | H36: Nguyễn Nhất Sinh | O36: Failing automated tests: MultiDatabaseIntegrationTest.authenticatedOnboardApiCreatesTenantAndRejectsDuplicateAliases
A37: MASTER-01-TC40 | B37: Verify update tenant status rejects invalid input (PATCH /api/v1/master/tenants/{id}/status). | C37: 1. Log in as Workspace Admin. 2. Send PATCH /api/v1/master/tenants/{id}/status with missing required fields or invalid values (empty text, wrong format, out-of-range numbers, non-existing IDs). 3. Check the response and the data in the system. | D37: HTTP 400 (or 404 for a non-existing ID) with success = false and an error message / field errors. No data is created or changed. | E37: Master platform is running. The Workspace Admin account has permission for this action. The target resource exists. | F37: Failed | G37: 14/10/2026 | H37: Nguyễn Nhất Sinh | O37: Failing automated tests: MultiDatabaseIntegrationTest.authenticatedOnboardApiCreatesTenantAndRejectsDuplicateAliases
A38: Security & tenant isolation
A39: MASTER-01-TC41 | B39: Verify platform admin APIs reject unauthenticated requests and tenant users. | C39: 1. Send GET /api/v1/master/tenants without an Authorization header. 2. Send the same request with a valid token of a tenant user (e.g. Tenant Admin). | D39: Step 1: HTTP 401, code UNAUTHORIZED. Step 2: HTTP 403, code FORBIDDEN (requires WORKSPACE_ADMIN). | E39: A tenant user account exists. | F39: Failed | G39: 14/10/2026 | H39: Nguyễn Nhất Sinh | O39: Failing automated tests: MultiDatabaseIntegrationTest.authenticatedOnboardApiCreatesTenantAndRejectsDuplicateAliases
A40: MASTER-01-TC42 | B40: Verify a Workspace Admin token cannot be used to read tenant data through tenant APIs. | C40: 1. Log in as Workspace Admin. 2. Call a tenant API (e.g. GET /api/v1/jobs) with header X-Tenant-ID = tenant A using the master token. | D40: The request is rejected (HTTP 401/403) and no tenant data is returned. | E40: Workspace Admin account exists; tenant A has data. | F40: Failed | G40: 14/10/2026 | H40: Nguyễn Nhất Sinh | O40: Failing automated tests: MultiDatabaseIntegrationTest.authenticatedOnboardApiCreatesTenantAndRejectsDuplicateAliases

Sheet MASTER-02
A2: Feature | B2: Two-Tier B2B Subscription Plans, V27 Snapshot & Quotas | R2: Passed
A3: Test requirement | B3: Verify the business rules and APIs of MASTER-02 - Two-Tier B2B Subscription Plans, V27 Snapshot & Quotas as specified in docs/features/Master-Platform/Subscription-Plans-Quotas.md. | R3: Failed
A4: Number of TCs | B4: =COUNTIF(A11:A2000,"*-TC*") -> 16 | R4: Pending
A5: Testing Round | B5: Passed | C5: Failed | D5: Pending | E5: N/A | R5: N/A
A6: Round 1 | B6: =COUNTIF($F$11:$F$2000,B$5) -> 16 | C6: =COUNTIF($F$11:$F$2000,C$5) -> 0 | D6: =COUNTIF($F$11:$F$2000,D$5) -> 0 | E6: =COUNTIF($F$11:$F$2000,E$5) -> 0
A7: Round 2 | B7: =COUNTIF($I$11:$I$2000,B$5) -> 0 | C7: =COUNTIF($I$11:$I$2000,C$5) -> 0 | D7: =COUNTIF($I$11:$I$2000,D$5) -> 0 | E7: =COUNTIF($I$11:$I$2000,E$5) -> 0
A8: Round 3 | B8: =COUNTIF($L$11:$L$2000,B$5) -> 0 | C8: =COUNTIF($L$11:$L$2000,C$5) -> 0 | D8: =COUNTIF($L$11:$L$2000,D$5) -> 0 | E8: =COUNTIF($L$11:$L$2000,E$5) -> 0
A10: Test Case ID | B10: Test Case Description | C10: Test Case Procedure | D10: Expected Results | E10: Pre-conditions | F10: Round 1 | G10: Test date | H10: Tester | I10: Round 2 | J10: Test date | K10: Tester | L10: Round 3 | M10: Test date | N10: Tester | O10: Note
A11: Get all plans (GET /api/v1/master/subscriptions)
A12: MASTER-02-TC05 | B12: Verify get all plans succeeds with valid input (GET /api/v1/master/subscriptions). | C12: 1. Log in as Workspace Admin. 2. Send GET /api/v1/master/subscriptions. 3. Check the response and the data shown in the system. | D12: HTTP 200. Response success = true and contains the requested data. | E12: Master platform is running. The Workspace Admin account has permission for this action. | F12: Passed | G12: 11/10/2026 | H12: Nguyễn Nhất Sinh | O12: Verified by automated tests: TwoTierSubscriptionArchitectureTest
A13: Create plan (POST /api/v1/master/subscriptions)
A14: MASTER-02-TC06 | B14: Verify create plan succeeds with valid input (POST /api/v1/master/subscriptions). | C14: 1. Log in as Workspace Admin. 2. Send POST /api/v1/master/subscriptions and a valid request body. 3. Check the response and the data shown in the system. | D14: HTTP 200/201. Response success = true; the record/action is saved and returned in the response. | E14: Master platform is running. The Workspace Admin account has permission for this action. | F14: Passed | G14: 11/10/2026 | H14: Nguyễn Nhất Sinh | O14: Verified by automated tests: TwoTierSubscriptionArchitectureTest
A15: MASTER-02-TC07 | B15: Verify create plan rejects invalid input (POST /api/v1/master/subscriptions). | C15: 1. Log in as Workspace Admin. 2. Send POST /api/v1/master/subscriptions with missing required fields or invalid values (empty text, wrong format, out-of-range numbers, non-existing IDs). 3. Check the response and the data in the system. | D15: HTTP 400 (or 404 for a non-existing ID) with success = false and an error message / field errors. No data is created or changed. | E15: Master platform is running. The Workspace Admin account has permission for this action. | F15: Passed | G15: 11/10/2026 | H15: Nguyễn Nhất Sinh | O15: Verified by automated tests: TwoTierSubscriptionArchitectureTest
A16: Get all tenant subscription instances (GET /api/v1/master/subscriptions/tenants)
A17: MASTER-02-TC08 | B17: Verify get all tenant subscription instances succeeds with valid input (GET /api/v1/master/subscriptions/tenants). | C17: 1. Log in as Workspace Admin. 2. Send GET /api/v1/master/subscriptions/tenants. 3. Check the response and the data shown in the system. | D17: HTTP 200. Response success = true and contains the requested data. | E17: Master platform is running. The Workspace Admin account has permission for this action. | F17: Passed | G17: 11/10/2026 | H17: Nguyễn Nhất Sinh | O17: Verified by automated tests: TwoTierSubscriptionArchitectureTest
A18: Get tenant subscription instance (GET /api/v1/master/subscriptions/tenants/{id})
A19: MASTER-02-TC09 | B19: Verify get tenant subscription instance succeeds with valid input (GET /api/v1/master/subscriptions/tenants/{id}). | C19: 1. Log in as Workspace Admin. 2. Send GET /api/v1/master/subscriptions/tenants/{id}. 3. Check the response and the data shown in the system. | D19: HTTP 200. Response success = true and contains the requested data. | E19: Master platform is running. The Workspace Admin account has permission for this action. The target resource exists. | F19: Passed | G19: 11/10/2026 | H19: Nguyễn Nhất Sinh | O19: Verified by automated tests: TwoTierSubscriptionArchitectureTest
A20: Assign or customize tenant subscription (PUT /api/v1/master/subscriptions/tenants/{id})
A21: MASTER-02-TC10 | B21: Verify assign or customize tenant subscription succeeds with valid input (PUT /api/v1/master/subscriptions/tenants/{id}). | C21: 1. Log in as Workspace Admin. 2. Send PUT /api/v1/master/subscriptions/tenants/{id} and a valid request body. 3. Check the response and the data shown in the system. | D21: HTTP 200. Response success = true; the changes are saved and returned. | E21: Master platform is running. The Workspace Admin account has permission for this action. The target resource exists. | F21: Passed | G21: 11/10/2026 | H21: Nguyễn Nhất Sinh | O21: Verified by automated tests: TwoTierSubscriptionArchitectureTest
A22: MASTER-02-TC11 | B22: Verify assign or customize tenant subscription rejects invalid input (PUT /api/v1/master/subscriptions/tenants/{id}). | C22: 1. Log in as Workspace Admin. 2. Send PUT /api/v1/master/subscriptions/tenants/{id} with missing required fields or invalid values (empty text, wrong format, out-of-range numbers, non-existing IDs). 3. Check the response and the data in the system. | D22: HTTP 400 (or 404 for a non-existing ID) with success = false and an error message / field errors. No data is created or changed. | E22: Master platform is running. The Workspace Admin account has permission for this action. The target resource exists. | F22: Passed | G22: 11/10/2026 | H22: Nguyễn Nhất Sinh | O22: Verified by automated tests: TwoTierSubscriptionArchitectureTest
A23: Get plan by id (GET /api/v1/master/subscriptions/{id})
A24: MASTER-02-TC12 | B24: Verify get plan by id succeeds with valid input (GET /api/v1/master/subscriptions/{id}). | C24: 1. Log in as Workspace Admin. 2. Send GET /api/v1/master/subscriptions/{id}. 3. Check the response and the data shown in the system. | D24: HTTP 200. Response success = true and contains the requested data. | E24: Master platform is running. The Workspace Admin account has permission for this action. The target resource exists. | F24: Passed | G24: 11/10/2026 | H24: Nguyễn Nhất Sinh | O24: Verified by automated tests: TwoTierSubscriptionArchitectureTest
A25: Plan (PUT /api/v1/master/subscriptions/{id})
A26: MASTER-02-TC13 | B26: Verify plan succeeds with valid input (PUT /api/v1/master/subscriptions/{id}). | C26: 1. Log in as Workspace Admin. 2. Send PUT /api/v1/master/subscriptions/{id} and a valid request body. 3. Check the response and the data shown in the system. | D26: HTTP 200. Response success = true; the changes are saved and returned. | E26: Master platform is running. The Workspace Admin account has permission for this action. The target resource exists. | F26: Passed | G26: 11/10/2026 | H26: Nguyễn Nhất Sinh | O26: Verified by automated tests: TwoTierSubscriptionArchitectureTest
A27: MASTER-02-TC14 | B27: Verify plan rejects invalid input (PUT /api/v1/master/subscriptions/{id}). | C27: 1. Log in as Workspace Admin. 2. Send PUT /api/v1/master/subscriptions/{id} with missing required fields or invalid values (empty text, wrong format, out-of-range numbers, non-existing IDs). 3. Check the response and the data in the system. | D27: HTTP 400 (or 404 for a non-existing ID) with success = false and an error message / field errors. No data is created or changed. | E27: Master platform is running. The Workspace Admin account has permission for this action. The target resource exists. | F27: Passed | G27: 11/10/2026 | H27: Nguyễn Nhất Sinh | O27: Verified by automated tests: TwoTierSubscriptionArchitectureTest
A28: Clone custom plan (POST /api/v1/master/subscriptions/{id}/clone-custom)
A29: MASTER-02-TC15 | B29: Verify clone custom plan succeeds with valid input (POST /api/v1/master/subscriptions/{id}/clone-custom). | C29: 1. Log in as Workspace Admin. 2. Send POST /api/v1/master/subscriptions/{id}/clone-custom and a valid request body. 3. Check the response and the data shown in the system. | D29: HTTP 200/201. Response success = true; the record/action is saved and returned in the response. | E29: Master platform is running. The Workspace Admin account has permission for this action. The target resource exists. | F29: Passed | G29: 11/10/2026 | H29: Nguyễn Nhất Sinh | O29: Verified by automated tests: TwoTierSubscriptionArchitectureTest
A30: MASTER-02-TC16 | B30: Verify clone custom plan rejects invalid input (POST /api/v1/master/subscriptions/{id}/clone-custom). | C30: 1. Log in as Workspace Admin. 2. Send POST /api/v1/master/subscriptions/{id}/clone-custom with missing required fields or invalid values (empty text, wrong format, out-of-range numbers, non-existing IDs). 3. Check the response and the data in the system. | D30: HTTP 400 (or 404 for a non-existing ID) with success = false and an error message / field errors. No data is created or changed. | E30: Master platform is running. The Workspace Admin account has permission for this action. The target resource exists. | F30: Passed | G30: 11/10/2026 | H30: Nguyễn Nhất Sinh | O30: Verified by automated tests: TwoTierSubscriptionArchitectureTest
A31: Status (PATCH /api/v1/master/subscriptions/{id}/status)
A32: MASTER-02-TC17 | B32: Verify status succeeds with valid input (PATCH /api/v1/master/subscriptions/{id}/status). | C32: 1. Log in as Workspace Admin. 2. Send PATCH /api/v1/master/subscriptions/{id}/status and a valid request body. 3. Check the response and the data shown in the system. | D32: HTTP 200. Response success = true; the changed fields are saved. | E32: Master platform is running. The Workspace Admin account has permission for this action. The target resource exists. | F32: Passed | G32: 11/10/2026 | H32: Nguyễn Nhất Sinh | O32: Verified by automated tests: TwoTierSubscriptionArchitectureTest
A33: MASTER-02-TC18 | B33: Verify status rejects invalid input (PATCH /api/v1/master/subscriptions/{id}/status). | C33: 1. Log in as Workspace Admin. 2. Send PATCH /api/v1/master/subscriptions/{id}/status with missing required fields or invalid values (empty text, wrong format, out-of-range numbers, non-existing IDs). 3. Check the response and the data in the system. | D33: HTTP 400 (or 404 for a non-existing ID) with success = false and an error message / field errors. No data is created or changed. | E33: Master platform is running. The Workspace Admin account has permission for this action. The target resource exists. | F33: Passed | G33: 11/10/2026 | H33: Nguyễn Nhất Sinh | O33: Verified by automated tests: TwoTierSubscriptionArchitectureTest
A34: Security & tenant isolation
A35: MASTER-02-TC19 | B35: Verify platform admin APIs reject unauthenticated requests and tenant users. | C35: 1. Send GET /api/v1/master/subscriptions without an Authorization header. 2. Send the same request with a valid token of a tenant user (e.g. Tenant Admin). | D35: Step 1: HTTP 401, code UNAUTHORIZED. Step 2: HTTP 403, code FORBIDDEN (requires WORKSPACE_ADMIN). | E35: A tenant user account exists. | F35: Passed | G35: 11/10/2026 | H35: Nguyễn Nhất Sinh | O35: Verified by automated tests: TwoTierSubscriptionArchitectureTest
A36: MASTER-02-TC20 | B36: Verify a Workspace Admin token cannot be used to read tenant data through tenant APIs. | C36: 1. Log in as Workspace Admin. 2. Call a tenant API (e.g. GET /api/v1/jobs) with header X-Tenant-ID = tenant A using the master token. | D36: The request is rejected (HTTP 401/403) and no tenant data is returned. | E36: Workspace Admin account exists; tenant A has data. | F36: Passed | G36: 11/10/2026 | H36: Nguyễn Nhất Sinh | O36: Verified by automated tests: TwoTierSubscriptionArchitectureTest

Sheet MASTER-03
A2: Feature | B2: Billing, VAT Invoicing & Payment Gateways (SePay/VNPay/PayPal) | R2: Passed
A3: Test requirement | B3: Verify the business rules and APIs of MASTER-03 - Billing, VAT Invoicing & Payment Gateways (SePay/VNPay/PayPal) as specified in docs/features/Master-Platform/Billing-Invoicing-Payment.md. | R3: Failed
A4: Number of TCs | B4: =COUNTIF(A11:A2000,"*-TC*") -> 20 | R4: Pending
A5: Testing Round | B5: Passed | C5: Failed | D5: Pending | E5: N/A | R5: N/A
A6: Round 1 | B6: =COUNTIF($F$11:$F$2000,B$5) -> 0 | C6: =COUNTIF($F$11:$F$2000,C$5) -> 20 | D6: =COUNTIF($F$11:$F$2000,D$5) -> 0 | E6: =COUNTIF($F$11:$F$2000,E$5) -> 0
A7: Round 2 | B7: =COUNTIF($I$11:$I$2000,B$5) -> 0 | C7: =COUNTIF($I$11:$I$2000,C$5) -> 0 | D7: =COUNTIF($I$11:$I$2000,D$5) -> 0 | E7: =COUNTIF($I$11:$I$2000,E$5) -> 0
A8: Round 3 | B8: =COUNTIF($L$11:$L$2000,B$5) -> 0 | C8: =COUNTIF($L$11:$L$2000,C$5) -> 0 | D8: =COUNTIF($L$11:$L$2000,D$5) -> 0 | E8: =COUNTIF($L$11:$L$2000,E$5) -> 0
A10: Test Case ID | B10: Test Case Description | C10: Test Case Procedure | D10: Expected Results | E10: Pre-conditions | F10: Round 1 | G10: Test date | H10: Tester | I10: Round 2 | J10: Test date | K10: Tester | L10: Round 3 | M10: Test date | N10: Tester | O10: Note
A11: Get all invoices (GET /api/v1/master/invoices)
A12: MASTER-03-TC05 | B12: Verify get all invoices succeeds with valid input (GET /api/v1/master/invoices). | C12: 1. Log in as Workspace Admin. 2. Send GET /api/v1/master/invoices. 3. Check the response and the data shown in the system. | D12: HTTP 200. Response success = true and contains the requested data. | E12: Master platform is running. The Workspace Admin account has permission for this action. | F12: Failed | G12: 14/10/2026 | H12: Nguyễn Nhất Sinh | O12: Failing automated tests: MasterBillingServiceTest.approveInvoice_PendingInvoice_ProvisionsTenantAndSendsMail
A13: Create invoice (POST /api/v1/master/invoices)
A14: MASTER-03-TC06 | B14: Verify create invoice succeeds with valid input (POST /api/v1/master/invoices). | C14: 1. Log in as Workspace Admin. 2. Send POST /api/v1/master/invoices and a valid request body. 3. Check the response and the data shown in the system. | D14: HTTP 200/201. Response success = true; the record/action is saved and returned in the response. | E14: Master platform is running. The Workspace Admin account has permission for this action. | F14: Failed | G14: 14/10/2026 | H14: Nguyễn Nhất Sinh | O14: Failing automated tests: MasterBillingServiceTest.approveInvoice_PendingInvoice_ProvisionsTenantAndSendsMail
A15: MASTER-03-TC07 | B15: Verify create invoice rejects invalid input (POST /api/v1/master/invoices). | C15: 1. Log in as Workspace Admin. 2. Send POST /api/v1/master/invoices with missing required fields or invalid values (empty text, wrong format, out-of-range numbers, non-existing IDs). 3. Check the response and the data in the system. | D15: HTTP 400 (or 404 for a non-existing ID) with success = false and an error message / field errors. No data is created or changed. | E15: Master platform is running. The Workspace Admin account has permission for this action. | F15: Failed | G15: 14/10/2026 | H15: Nguyễn Nhất Sinh | O15: Failing automated tests: MasterBillingServiceTest.approveInvoice_PendingInvoice_ProvisionsTenantAndSendsMail
A16: Get invoice by id (GET /api/v1/master/invoices/{id})
A17: MASTER-03-TC08 | B17: Verify get invoice by id succeeds with valid input (GET /api/v1/master/invoices/{id}). | C17: 1. Log in as Workspace Admin. 2. Send GET /api/v1/master/invoices/{id}. 3. Check the response and the data shown in the system. | D17: HTTP 200. Response success = true and contains the requested data. | E17: Master platform is running. The Workspace Admin account has permission for this action. The target resource exists. | F17: Failed | G17: 14/10/2026 | H17: Nguyễn Nhất Sinh | O17: Failing automated tests: MasterBillingServiceTest.approveInvoice_PendingInvoice_ProvisionsTenantAndSendsMail
A18: Approve invoice (POST /api/v1/master/invoices/{id}/approve)
A19: MASTER-03-TC09 | B19: Verify approve invoice succeeds with valid input (POST /api/v1/master/invoices/{id}/approve). | C19: 1. Log in as Workspace Admin. 2. Send POST /api/v1/master/invoices/{id}/approve and a valid request body. 3. Check the response and the data shown in the system. | D19: HTTP 200/201. Response success = true; the record/action is saved and returned in the response. | E19: Master platform is running. The Workspace Admin account has permission for this action. The target resource exists. | F19: Failed | G19: 14/10/2026 | H19: Nguyễn Nhất Sinh | O19: Failing automated tests: MasterBillingServiceTest.approveInvoice_PendingInvoice_ProvisionsTenantAndSendsMail
A20: MASTER-03-TC10 | B20: Verify approve invoice rejects invalid input (POST /api/v1/master/invoices/{id}/approve). | C20: 1. Log in as Workspace Admin. 2. Send POST /api/v1/master/invoices/{id}/approve with missing required fields or invalid values (empty text, wrong format, out-of-range numbers, non-existing IDs). 3. Check the response and the data in the system. | D20: HTTP 400 (or 404 for a non-existing ID) with success = false and an error message / field errors. No data is created or changed. | E20: Master platform is running. The Workspace Admin account has permission for this action. The target resource exists. | F20: Failed | G20: 14/10/2026 | H20: Nguyễn Nhất Sinh | O20: Failing automated tests: MasterBillingServiceTest.approveInvoice_PendingInvoice_ProvisionsTenantAndSendsMail
A21: Update invoice status (PATCH /api/v1/master/invoices/{id}/status)
A22: MASTER-03-TC11 | B22: Verify update invoice status succeeds with valid input (PATCH /api/v1/master/invoices/{id}/status). | C22: 1. Log in as Workspace Admin. 2. Send PATCH /api/v1/master/invoices/{id}/status and a valid request body. 3. Check the response and the data shown in the system. | D22: HTTP 200. Response success = true; the changed fields are saved. | E22: Master platform is running. The Workspace Admin account has permission for this action. The target resource exists. | F22: Failed | G22: 14/10/2026 | H22: Nguyễn Nhất Sinh | O22: Failing automated tests: MasterBillingServiceTest.approveInvoice_PendingInvoice_ProvisionsTenantAndSendsMail
A23: MASTER-03-TC12 | B23: Verify update invoice status rejects invalid input (PATCH /api/v1/master/invoices/{id}/status). | C23: 1. Log in as Workspace Admin. 2. Send PATCH /api/v1/master/invoices/{id}/status with missing required fields or invalid values (empty text, wrong format, out-of-range numbers, non-existing IDs). 3. Check the response and the data in the system. | D23: HTTP 400 (or 404 for a non-existing ID) with success = false and an error message / field errors. No data is created or changed. | E23: Master platform is running. The Workspace Admin account has permission for this action. The target resource exists. | F23: Failed | G23: 14/10/2026 | H23: Nguyễn Nhất Sinh | O23: Failing automated tests: MasterBillingServiceTest.approveInvoice_PendingInvoice_ProvisionsTenantAndSendsMail
A24: Verify return (POST /api/v1/public/checkout/paypal/verify-return)
A25: MASTER-03-TC13 | B25: Verify verify return succeeds with valid input (POST /api/v1/public/checkout/paypal/verify-return). | C25: 1. Do not log in (public endpoint). 2. Send POST /api/v1/public/checkout/paypal/verify-return and a valid request body. 3. Check the response and the data shown in the system. | D25: HTTP 200/201. Response success = true; the record/action is saved and returned in the response. | E25: Master platform is running. | F25: Failed | G25: 14/10/2026 | H25: Nguyễn Nhất Sinh | O25: Failing automated tests: MasterBillingServiceTest.approveInvoice_PendingInvoice_ProvisionsTenantAndSendsMail
A26: MASTER-03-TC14 | B26: Verify verify return rejects invalid input (POST /api/v1/public/checkout/paypal/verify-return). | C26: 1. Do not log in (public endpoint). 2. Send POST /api/v1/public/checkout/paypal/verify-return with missing required fields or invalid values (empty text, wrong format, out-of-range numbers, non-existing IDs). 3. Check the response and the data in the system. | D26: HTTP 400 (or 404 for a non-existing ID) with success = false and an error message / field errors. No data is created or changed. | E26: Master platform is running. | F26: Failed | G26: 14/10/2026 | H26: Nguyễn Nhất Sinh | O26: Failing automated tests: MasterBillingServiceTest.approveInvoice_PendingInvoice_ProvisionsTenantAndSendsMail
A27: Handle se pay webhook (POST /api/v1/public/checkout/sepay-webhook)
A28: MASTER-03-TC15 | B28: Verify handle se pay webhook succeeds with valid input (POST /api/v1/public/checkout/sepay-webhook). | C28: 1. Do not log in (public endpoint). 2. Send POST /api/v1/public/checkout/sepay-webhook and a valid request body. 3. Check the response and the data shown in the system. | D28: HTTP 200/201. Response success = true; the record/action is saved and returned in the response. | E28: Master platform is running. | F28: Failed | G28: 14/10/2026 | H28: Nguyễn Nhất Sinh | O28: Failing automated tests: MasterBillingServiceTest.approveInvoice_PendingInvoice_ProvisionsTenantAndSendsMail
A29: MASTER-03-TC16 | B29: Verify handle se pay webhook rejects invalid input (POST /api/v1/public/checkout/sepay-webhook). | C29: 1. Do not log in (public endpoint). 2. Send POST /api/v1/public/checkout/sepay-webhook with missing required fields or invalid values (empty text, wrong format, out-of-range numbers, non-existing IDs). 3. Check the response and the data in the system. | D29: HTTP 400 (or 404 for a non-existing ID) with success = false and an error message / field errors. No data is created or changed. | E29: Master platform is running. | F29: Failed | G29: 14/10/2026 | H29: Nguyễn Nhất Sinh | O29: Failing automated tests: MasterBillingServiceTest.approveInvoice_PendingInvoice_ProvisionsTenantAndSendsMail
A30: Create payment url (POST /api/v1/public/checkout/vnpay/create-url)
A31: MASTER-03-TC17 | B31: Verify create payment url succeeds with valid input (POST /api/v1/public/checkout/vnpay/create-url). | C31: 1. Do not log in (public endpoint). 2. Send POST /api/v1/public/checkout/vnpay/create-url and a valid request body. 3. Check the response and the data shown in the system. | D31: HTTP 200/201. Response success = true; the record/action is saved and returned in the response. | E31: Master platform is running. | F31: Failed | G31: 14/10/2026 | H31: Nguyễn Nhất Sinh | O31: Failing automated tests: MasterBillingServiceTest.approveInvoice_PendingInvoice_ProvisionsTenantAndSendsMail
A32: MASTER-03-TC18 | B32: Verify create payment url rejects invalid input (POST /api/v1/public/checkout/vnpay/create-url). | C32: 1. Do not log in (public endpoint). 2. Send POST /api/v1/public/checkout/vnpay/create-url with missing required fields or invalid values (empty text, wrong format, out-of-range numbers, non-existing IDs). 3. Check the response and the data in the system. | D32: HTTP 400 (or 404 for a non-existing ID) with success = false and an error message / field errors. No data is created or changed. | E32: Master platform is running. | F32: Failed | G32: 14/10/2026 | H32: Nguyễn Nhất Sinh | O32: Failing automated tests: MasterBillingServiceTest.approveInvoice_PendingInvoice_ProvisionsTenantAndSendsMail
A33: Handle ipn (GET /api/v1/public/checkout/vnpay/ipn)
A34: MASTER-03-TC19 | B34: Verify handle ipn succeeds with valid input (GET /api/v1/public/checkout/vnpay/ipn). | C34: 1. Do not log in (public endpoint). 2. Send GET /api/v1/public/checkout/vnpay/ipn. 3. Check the response and the data shown in the system. | D34: HTTP 200. Response success = true and contains the requested data. | E34: Master platform is running. | F34: Failed | G34: 14/10/2026 | H34: Nguyễn Nhất Sinh | O34: Failing automated tests: MasterBillingServiceTest.approveInvoice_PendingInvoice_ProvisionsTenantAndSendsMail
A35: Verify return (GET /api/v1/public/checkout/vnpay/verify-return)
A36: MASTER-03-TC20 | B36: Verify verify return succeeds with valid input (GET /api/v1/public/checkout/vnpay/verify-return). | C36: 1. Do not log in (public endpoint). 2. Send GET /api/v1/public/checkout/vnpay/verify-return. 3. Check the response and the data shown in the system. | D36: HTTP 200. Response success = true and contains the requested data. | E36: Master platform is running. | F36: Failed | G36: 14/10/2026 | H36: Nguyễn Nhất Sinh | O36: Failing automated tests: MasterBillingServiceTest.approveInvoice_PendingInvoice_ProvisionsTenantAndSendsMail
A37: Handle se pay webhook (POST /api/v1/public/sepay/webhook)
A38: MASTER-03-TC21 | B38: Verify handle se pay webhook succeeds with valid input (POST /api/v1/public/sepay/webhook). | C38: 1. Do not log in (public endpoint). 2. Send POST /api/v1/public/sepay/webhook and a valid request body. 3. Check the response and the data shown in the system. | D38: HTTP 200/201. Response success = true; the record/action is saved and returned in the response. | E38: Master platform is running. | F38: Failed | G38: 14/10/2026 | H38: Nguyễn Nhất Sinh | O38: Failing automated tests: MasterBillingServiceTest.approveInvoice_PendingInvoice_ProvisionsTenantAndSendsMail
A39: MASTER-03-TC22 | B39: Verify handle se pay webhook rejects invalid input (POST /api/v1/public/sepay/webhook). | C39: 1. Do not log in (public endpoint). 2. Send POST /api/v1/public/sepay/webhook with missing required fields or invalid values (empty text, wrong format, out-of-range numbers, non-existing IDs). 3. Check the response and the data in the system. | D39: HTTP 400 (or 404 for a non-existing ID) with success = false and an error message / field errors. No data is created or changed. | E39: Master platform is running. | F39: Failed | G39: 14/10/2026 | H39: Nguyễn Nhất Sinh | O39: Failing automated tests: MasterBillingServiceTest.approveInvoice_PendingInvoice_ProvisionsTenantAndSendsMail
A40: Security & tenant isolation
A41: MASTER-03-TC23 | B41: Verify platform admin APIs reject unauthenticated requests and tenant users. | C41: 1. Send GET /api/v1/master/invoices without an Authorization header. 2. Send the same request with a valid token of a tenant user (e.g. Tenant Admin). | D41: Step 1: HTTP 401, code UNAUTHORIZED. Step 2: HTTP 403, code FORBIDDEN (requires WORKSPACE_ADMIN). | E41: A tenant user account exists. | F41: Failed | G41: 14/10/2026 | H41: Nguyễn Nhất Sinh | O41: Failing automated tests: MasterBillingServiceTest.approveInvoice_PendingInvoice_ProvisionsTenantAndSendsMail
A42: MASTER-03-TC24 | B42: Verify a Workspace Admin token cannot be used to read tenant data through tenant APIs. | C42: 1. Log in as Workspace Admin. 2. Call a tenant API (e.g. GET /api/v1/jobs) with header X-Tenant-ID = tenant A using the master token. | D42: The request is rejected (HTTP 401/403) and no tenant data is returned. | E42: Workspace Admin account exists; tenant A has data. | F42: Failed | G42: 14/10/2026 | H42: Nguyễn Nhất Sinh | O42: Failing automated tests: MasterBillingServiceTest.approveInvoice_PendingInvoice_ProvisionsTenantAndSendsMail

Sheet MASTER-04
A2: Feature | B2: Self-serve Checkout & Click-wrap Legal Consent (Decree 13/2023/ND-CP) | R2: Passed
A3: Test requirement | B3: Verify the business rules and APIs of MASTER-04 - Self-serve Checkout & Click-wrap Legal Consent (Decree 13/2023/ND-CP) as specified in docs/features/Master-Platform/Checkout-Clickwrap-Consent.md. | R3: Failed
A4: Number of TCs | B4: =COUNTIF(A11:A2000,"*-TC*") -> 6 | R4: Pending
A5: Testing Round | B5: Passed | C5: Failed | D5: Pending | E5: N/A | R5: N/A
A6: Round 1 | B6: =COUNTIF($F$11:$F$2000,B$5) -> 0 | C6: =COUNTIF($F$11:$F$2000,C$5) -> 4 | D6: =COUNTIF($F$11:$F$2000,D$5) -> 0 | E6: =COUNTIF($F$11:$F$2000,E$5) -> 2
A7: Round 2 | B7: =COUNTIF($I$11:$I$2000,B$5) -> 0 | C7: =COUNTIF($I$11:$I$2000,C$5) -> 0 | D7: =COUNTIF($I$11:$I$2000,D$5) -> 0 | E7: =COUNTIF($I$11:$I$2000,E$5) -> 0
A8: Round 3 | B8: =COUNTIF($L$11:$L$2000,B$5) -> 0 | C8: =COUNTIF($L$11:$L$2000,C$5) -> 0 | D8: =COUNTIF($L$11:$L$2000,D$5) -> 0 | E8: =COUNTIF($L$11:$L$2000,E$5) -> 0
A10: Test Case ID | B10: Test Case Description | C10: Test Case Procedure | D10: Expected Results | E10: Pre-conditions | F10: Round 1 | G10: Test date | H10: Tester | I10: Round 2 | J10: Test date | K10: Tester | L10: Round 3 | M10: Test date | N10: Tester | O10: Note
A11: Submit checkout (POST /api/v1/public/checkout)
A12: MASTER-04-TC04 | B12: Verify submit checkout succeeds with valid input (POST /api/v1/public/checkout). | C12: 1. Do not log in (public endpoint). 2. Send POST /api/v1/public/checkout and a valid request body. 3. Check the response and the data shown in the system. | D12: HTTP 200/201. Response success = true; the record/action is saved and returned in the response. | E12: Master platform is running. | F12: Failed | G12: 14/10/2026 | H12: Nguyễn Nhất Sinh | O12: Failing automated tests: MasterBillingServiceTest.approveInvoice_PendingInvoice_ProvisionsTenantAndSendsMail, PublicCheckoutControllerTest.getPublicPlans_ReturnsActivePlansWithVndPricing
A13: MASTER-04-TC05 | B13: Verify submit checkout rejects invalid input (POST /api/v1/public/checkout). | C13: 1. Do not log in (public endpoint). 2. Send POST /api/v1/public/checkout with missing required fields or invalid values (empty text, wrong format, out-of-range numbers, non-existing IDs). 3. Check the response and the data in the system. | D13: HTTP 400 (or 404 for a non-existing ID) with success = false and an error message / field errors. No data is created or changed. | E13: Master platform is running. | F13: Failed | G13: 14/10/2026 | H13: Nguyễn Nhất Sinh | O13: Failing automated tests: MasterBillingServiceTest.approveInvoice_PendingInvoice_ProvisionsTenantAndSendsMail, PublicCheckoutControllerTest.getPublicPlans_ReturnsActivePlansWithVndPricing
A14: Get public plans (GET /api/v1/public/checkout/plans)
A15: MASTER-04-TC06 | B15: Verify get public plans succeeds with valid input (GET /api/v1/public/checkout/plans). | C15: 1. Do not log in (public endpoint). 2. Send GET /api/v1/public/checkout/plans. 3. Check the response and the data shown in the system. | D15: HTTP 200. Response success = true and contains the requested data. | E15: Master platform is running. | F15: Failed | G15: 14/10/2026 | H15: Nguyễn Nhất Sinh | O15: Failing automated tests: MasterBillingServiceTest.approveInvoice_PendingInvoice_ProvisionsTenantAndSendsMail, PublicCheckoutControllerTest.getPublicPlans_ReturnsActivePlansWithVndPricing
A16: Invoice (GET /api/v1/public/checkout/status/{id})
A17: MASTER-04-TC07 | B17: Verify invoice succeeds with valid input (GET /api/v1/public/checkout/status/{id}). | C17: 1. Do not log in (public endpoint). 2. Send GET /api/v1/public/checkout/status/{id}. 3. Check the response and the data shown in the system. | D17: HTTP 200. Response success = true and contains the requested data. | E17: Master platform is running. The target resource exists. | F17: Failed | G17: 14/10/2026 | H17: Nguyễn Nhất Sinh | O17: Failing automated tests: MasterBillingServiceTest.approveInvoice_PendingInvoice_ProvisionsTenantAndSendsMail, PublicCheckoutControllerTest.getPublicPlans_ReturnsActivePlansWithVndPricing
A18: Security & tenant isolation
A19: MASTER-04-TC08 | B19: Verify platform admin APIs reject unauthenticated requests and tenant users. | C19: 1. Send without an Authorization header. 2. Send the same request with a valid token of a tenant user (e.g. Tenant Admin). | D19: Step 1: HTTP 401, code UNAUTHORIZED. Step 2: HTTP 403, code FORBIDDEN (requires WORKSPACE_ADMIN). | E19: A tenant user account exists. | F19: N/A | H19: Nguyễn Nhất Sinh | O19: All endpoints of this feature are public (permitAll).
